INFO:Blockchain:Initializing blockchain and network on port 5000
INFO:Blockchain:Initializing blockchain and network on port 5000
INFO:Blockchain:Initializing blockchain and network on port 5000
INFO:Blockchain:Starting network thread (attempt 1/3)
INFO:Blockchain:Network thread started
ERROR:Blockchain:Network startup failed: 'BlockchainNetwork' object has no attribute 'ssl_context'
INFO:Blockchain:Scheduling periodic sync task
INFO:Blockchain:Waiting for network to initialize
INFO:Blockchain:Attempting health check 1/5 on https://127.0.0.1:5000/get_chain
WARNING:Blockchain:Health check attempt 1 failed: Cannot connect to host 127.0.0.1:5000 ssl:<ssl.SSLContext object at 0x000001AE90EC59A0> [The remote computer refused the network connection]
INFO:Blockchain:Attempting health check 2/5 on https://127.0.0.1:5000/get_chain
WARNING:Blockchain:Health check attempt 2 failed: Cannot connect to host 127.0.0.1:5000 ssl:<ssl.SSLContext object at 0x000001AE90EC59A0> [The remote computer refused the network connection]
INFO:Blockchain:Attempting health check 3/5 on https://127.0.0.1:5000/get_chain
WARNING:Blockchain:Health check attempt 3 failed: Cannot connect to host 127.0.0.1:5000 ssl:<ssl.SSLContext object at 0x000001AE90EC59A0> [The remote computer refused the network connection]
INFO:Blockchain:Attempting health check 4/5 on https://127.0.0.1:5000/get_chain
WARNING:Blockchain:Health check attempt 4 failed: Cannot connect to host 127.0.0.1:5000 ssl:<ssl.SSLContext object at 0x000001AE90EC59A0> [The remote computer refused the network connection]
INFO:Blockchain:Attempting health check 5/5 on https://127.0.0.1:5000/get_chain
WARNING:Blockchain:Health check attempt 5 failed: Cannot connect to host 127.0.0.1:5000 ssl:<ssl.SSLContext object at 0x000001AE90EC59A0> [The remote computer refused the network connection]
ERROR:Blockchain:All health check attempts failed
ERROR:Blockchain:Health check failed after retries, exiting...
ERROR:asyncio:Task was destroyed but it is pending!
task: <Task pending name='Task-2' coro=<BlockchainNetwork.start_periodic_sync.<locals>.sync_and_discover() running at C:\Users\jdman\new_coin\network.py:287>>
INFO:Blockchain:Initializing blockchain and network on port 5000
INFO:Blockchain:Setting up network server on 127.0.0.1:5000
INFO:Blockchain:Network thread started
INFO:Blockchain:Waiting for network to initialize
INFO:Blockchain:Network server running on 127.0.0.1:5000
INFO:Blockchain:Starting periodic sync and discovery loop
INFO:Blockchain:Initial peer discovery completed
INFO:Blockchain:Initial peer discovery completed
INFO:Blockchain:Sync loop iteration starting
INFO:Blockchain:Sync loop iteration completed
INFO:Blockchain:Starting periodic sync and discovery loop
INFO:Blockchain:Initial peer discovery completed
INFO:Blockchain:Initial peer discovery completed
INFO:Blockchain:Sync loop iteration starting
INFO:Blockchain:Sync loop iteration completed
INFO:Blockchain:Initial peer discovery completed
INFO:Blockchain:Initial peer discovery completed
INFO:Blockchain:Attempting health check 1/5 on https://127.0.0.1:5000/get_chain
INFO:aiohttp.access:127.0.0.1 [10/Mar/2025:19:34:14 -0800] "GET /get_chain HTTP/1.1" 200 525 "-" "Python/3.13 aiohttp/3.11.13"
INFO:Blockchain:Health check response: 200
INFO:Blockchain:Initializing GUI
INFO:Blockchain:Starting GUI main loop
INFO:Blockchain:Sync loop iteration starting
INFO:Blockchain:Sync loop iteration completed
INFO:Blockchain:Sync loop iteration starting
INFO:Blockchain:Sync loop iteration completed
INFO:Blockchain:Mining task started in separate thread
INFO:Blockchain:Starting to mine block 1 with difficulty 1
INFO:Blockchain:Block 1 mined with hash 061f626e3263a9a94a3713b32531f0b0045c10749b62c715a7beb12934e21dff
INFO:Blockchain:Transaction 3c025a1a is coinbase, auto-validated
INFO:Blockchain:Block 061f626e validated successfully
INFO:Blockchain:Added block 1 to chain: 061f626e
INFO:Blockchain:Successfully mined block 1
INFO:Blockchain:Starting to mine block 2 with difficulty 1
INFO:Blockchain:Block 2 mined with hash 065a93e487a180c68ea0031642d0b9be539e94ac50ed223fa0239c5cdcdf3c63
INFO:Blockchain:Transaction 94eb65ec is coinbase, auto-validated
INFO:Blockchain:Block 065a93e4 validated successfully
INFO:Blockchain:Added block 2 to chain: 065a93e4
INFO:Blockchain:Successfully mined block 2
INFO:Blockchain:Starting to mine block 3 with difficulty 1
INFO:Blockchain:Block 3 mined with hash 015e645ab2fd3b45ae7972967c3f8a58dec882d319ae6ffddf7066a3d22b0fc2
INFO:Blockchain:Transaction 12614ce8 is coinbase, auto-validated
INFO:Blockchain:Block 015e645a validated successfully
INFO:Blockchain:Added block 3 to chain: 015e645a
INFO:Blockchain:Successfully mined block 3
INFO:Blockchain:Starting to mine block 4 with difficulty 1
INFO:Blockchain:Block 4 mined with hash 014face6a283b5643e31aecd829d477439a6e241a39d11349faf51c9e9c1c2a5
INFO:Blockchain:Transaction 66b1bfc9 is coinbase, auto-validated
INFO:Blockchain:Block 014face6 validated successfully
INFO:Blockchain:Added block 4 to chain: 014face6
INFO:Blockchain:Successfully mined block 4
INFO:Blockchain:Starting to mine block 5 with difficulty 1
INFO:Blockchain:Block 5 mined with hash 04a1fe2552b1d9f6edbf93ceae3a31656655d473e71c622affd14db02e11b7db
INFO:Blockchain:Transaction b5275f29 is coinbase, auto-validated
INFO:Blockchain:Block 04a1fe25 validated successfully
INFO:Blockchain:Added block 5 to chain: 04a1fe25
INFO:Blockchain:Successfully mined block 5
INFO:Blockchain:Starting to mine block 6 with difficulty 1
INFO:Blockchain:Block 6 mined with hash 0d5c46f5ef1ff7e4719e1d547c7aa129048e10ec7aa03462fe760808a5aa2976
INFO:Blockchain:Transaction 74e7be56 is coinbase, auto-validated
INFO:Blockchain:Block 0d5c46f5 validated successfully
INFO:Blockchain:Added block 6 to chain: 0d5c46f5
INFO:Blockchain:Successfully mined block 6
INFO:Blockchain:Starting to mine block 7 with difficulty 1
INFO:Blockchain:Block 7 mined with hash 0c8a5238668e612a4a161dcb86fb768a4ffee3d57f05d644c747a79039ebebcb
INFO:Blockchain:Transaction 22a0b9f8 is coinbase, auto-validated
INFO:Blockchain:Block 0c8a5238 validated successfully
INFO:Blockchain:Added block 7 to chain: 0c8a5238
INFO:Blockchain:Successfully mined block 7
INFO:Blockchain:Starting to mine block 8 with difficulty 1
INFO:Blockchain:Block 8 mined with hash 0e82a22970ceaca4b7b4a932bf32a8e9625be332e890ffc179f43640b3fc6267
INFO:Blockchain:Transaction 392f332c is coinbase, auto-validated
INFO:Blockchain:Block 0e82a229 validated successfully
INFO:Blockchain:Added block 8 to chain: 0e82a229
INFO:Blockchain:Successfully mined block 8
INFO:Blockchain:Starting to mine block 9 with difficulty 1
INFO:Blockchain:Block 9 mined with hash 02e0a6e9108651c1431211a0108c00745bdeef1bb1a38c56d29ba4209697e3ca
INFO:Blockchain:Transaction 88d9bb47 is coinbase, auto-validated
INFO:Blockchain:Block 02e0a6e9 validated successfully
INFO:Blockchain:Added block 9 to chain: 02e0a6e9
INFO:Blockchain:Successfully mined block 9
INFO:Blockchain:Starting to mine block 10 with difficulty 1
INFO:Blockchain:Block 10 mined with hash 0a35076880f7ecd25ff50f328309111e246016502bff203e133b6a1d9b900f35
INFO:Blockchain:Transaction f6743469 is coinbase, auto-validated
INFO:Blockchain:Block 0a350768 validated successfully
INFO:Blockchain:Added block 10 to chain: 0a350768
INFO:Blockchain:Successfully mined block 10
INFO:Blockchain:Mining thread stopped
INFO:Blockchain:Sync loop iteration starting
INFO:Blockchain:Sync loop iteration completed
INFO:Blockchain:Sync loop iteration starting
INFO:Blockchain:Sync loop iteration completed
INFO:Blockchain:Sync loop iteration starting
INFO:Blockchain:Sync loop iteration completed
INFO:Blockchain:Sync loop iteration starting
INFO:Blockchain:Sync loop iteration completed
INFO:Blockchain:Initializing blockchain and network on port 12649
INFO:Blockchain:Setting up network server on 127.0.0.1:12649
INFO:Blockchain:Network thread started
INFO:Blockchain:Waiting for network to initialize
INFO:Blockchain:Network server running on 127.0.0.1:12649
INFO:Blockchain:Starting periodic sync and discovery loop
INFO:Blockchain:Starting periodic sync and discovery loop
INFO:aiohttp.access:127.0.0.1 [10/Mar/2025:19:34:52 -0800] "GET /get_chain HTTP/1.1" 200 7915 "-" "Python/3.13 aiohttp/3.11.13"
INFO:Blockchain:Added peer node5000: 127.0.0.1:5000
INFO:aiohttp.access:127.0.0.1 [10/Mar/2025:19:34:52 -0800] "GET /get_chain HTTP/1.1" 200 7915 "-" "Python/3.13 aiohttp/3.11.13"
INFO:Blockchain:Sync loop iteration starting
INFO:Blockchain:Sync loop iteration completed
INFO:Blockchain:Sync loop iteration starting
INFO:Blockchain:Sync loop iteration completed
WARNING:Blockchain:Peer node12649 failed authentication
INFO:aiohttp.access:127.0.0.1 [10/Mar/2025:19:34:52 -0800] "POST /announce_peer HTTP/1.1" 403 119 "-" "Python/3.13 aiohttp/3.11.13"
WARNING:Blockchain:Failed to announce to node5000: 403
INFO:aiohttp.access:127.0.0.1 [10/Mar/2025:19:34:52 -0800] "GET /get_peers HTTP/1.1" 200 161 "-" "Python/3.13 aiohttp/3.11.13"
INFO:Blockchain:Initial peer discovery completed
INFO:Blockchain:Initial peer discovery completed
INFO:Blockchain:Sync loop iteration starting
INFO:aiohttp.access:127.0.0.1 [10/Mar/2025:19:34:52 -0800] "GET /get_peers HTTP/1.1" 200 161 "-" "Python/3.13 aiohttp/3.11.13"
INFO:aiohttp.access:127.0.0.1 [10/Mar/2025:19:34:52 -0800] "GET /get_chain HTTP/1.1" 200 7915 "-" "Python/3.13 aiohttp/3.11.13"
INFO:Blockchain:Initial peer discovery completed
INFO:Blockchain:Initial peer discovery completed
INFO:Blockchain:Sync loop iteration starting
INFO:aiohttp.access:127.0.0.1 [10/Mar/2025:19:34:52 -0800] "GET /get_chain HTTP/1.1" 200 7915 "-" "Python/3.13 aiohttp/3.11.13"
INFO:aiohttp.access:127.0.0.1 [10/Mar/2025:19:34:52 -0800] "GET /get_chain HTTP/1.1" 200 7915 "-" "Python/3.13 aiohttp/3.11.13"
INFO:aiohttp.access:127.0.0.1 [10/Mar/2025:19:34:52 -0800] "GET /get_chain HTTP/1.1" 200 7915 "-" "Python/3.13 aiohttp/3.11.13"
WARNING:Blockchain:Peer node12649 failed authentication
INFO:aiohttp.access:127.0.0.1 [10/Mar/2025:19:34:52 -0800] "POST /announce_peer HTTP/1.1" 403 119 "-" "Python/3.13 aiohttp/3.11.13"
INFO:aiohttp.access:127.0.0.1 [10/Mar/2025:19:34:52 -0800] "GET /get_peers HTTP/1.1" 200 161 "-" "Python/3.13 aiohttp/3.11.13"
WARNING:Blockchain:Failed to announce to node5000: 403
INFO:Blockchain:Sync loop iteration completed
INFO:Blockchain:Initial peer discovery completed
WARNING:Blockchain:Peer node12649 failed authentication
INFO:aiohttp.access:127.0.0.1 [10/Mar/2025:19:34:52 -0800] "POST /announce_peer HTTP/1.1" 403 119 "-" "Python/3.13 aiohttp/3.11.13"
WARNING:Blockchain:Failed to announce to node5000: 403
INFO:Blockchain:Sync loop iteration completed
INFO:aiohttp.access:127.0.0.1 [10/Mar/2025:19:34:52 -0800] "GET /get_peers HTTP/1.1" 200 161 "-" "Python/3.13 aiohttp/3.11.13"
INFO:Blockchain:Initial peer discovery completed
INFO:Blockchain:Attempting health check 1/5 on https://127.0.0.1:12649/get_chain
INFO:aiohttp.access:127.0.0.1 [10/Mar/2025:19:34:54 -0800] "GET /get_chain HTTP/1.1" 200 7915 "-" "Python/3.13 aiohttp/3.11.13"
INFO:Blockchain:Health check response: 200
INFO:Blockchain:Initializing GUI
INFO:Blockchain:Starting GUI main loop
INFO:Blockchain:Sync loop iteration starting
INFO:Blockchain:Sync loop iteration completed
INFO:Blockchain:Sync loop iteration starting
INFO:Blockchain:Sync loop iteration completed
INFO:Blockchain:Sync loop iteration starting
INFO:Blockchain:Sync loop iteration starting
INFO:aiohttp.access:127.0.0.1 [10/Mar/2025:19:35:02 -0800] "GET /get_chain HTTP/1.1" 200 7915 "-" "Python/3.13 aiohttp/3.11.13"
INFO:aiohttp.access:127.0.0.1 [10/Mar/2025:19:35:02 -0800] "GET /get_chain HTTP/1.1" 200 7915 "-" "Python/3.13 aiohttp/3.11.13"
WARNING:Blockchain:Peer node12649 failed authentication
INFO:aiohttp.access:127.0.0.1 [10/Mar/2025:19:35:02 -0800] "POST /announce_peer HTTP/1.1" 403 119 "-" "Python/3.13 aiohttp/3.11.13"
WARNING:Blockchain:Failed to announce to node5000: 403
INFO:Blockchain:Sync loop iteration completed
WARNING:Blockchain:Peer node12649 failed authentication
INFO:aiohttp.access:127.0.0.1 [10/Mar/2025:19:35:02 -0800] "POST /announce_peer HTTP/1.1" 403 119 "-" "Python/3.13 aiohttp/3.11.13"
WARNING:Blockchain:Failed to announce to node5000: 403
INFO:Blockchain:Sync loop iteration completed
INFO:Blockchain:Initial peer discovery completed
INFO:Blockchain:Initial peer discovery completed
INFO:Blockchain:Sync loop iteration starting
INFO:Blockchain:Sync loop iteration completed
INFO:Blockchain:Sync loop iteration starting
INFO:Blockchain:Sync loop iteration completed
INFO:Blockchain:Sync loop iteration starting
INFO:Blockchain:Sync loop iteration starting
INFO:aiohttp.access:127.0.0.1 [10/Mar/2025:19:35:12 -0800] "GET /get_chain HTTP/1.1" 200 7915 "-" "Python/3.13 aiohttp/3.11.13"
INFO:aiohttp.access:127.0.0.1 [10/Mar/2025:19:35:12 -0800] "GET /get_chain HTTP/1.1" 200 7915 "-" "Python/3.13 aiohttp/3.11.13"
WARNING:Blockchain:Peer node12649 failed authentication
INFO:aiohttp.access:127.0.0.1 [10/Mar/2025:19:35:12 -0800] "POST /announce_peer HTTP/1.1" 403 119 "-" "Python/3.13 aiohttp/3.11.13"
WARNING:Blockchain:Failed to announce to node5000: 403
INFO:Blockchain:Sync loop iteration completed
WARNING:Blockchain:Peer node12649 failed authentication
INFO:aiohttp.access:127.0.0.1 [10/Mar/2025:19:35:12 -0800] "POST /announce_peer HTTP/1.1" 403 119 "-" "Python/3.13 aiohttp/3.11.13"
WARNING:Blockchain:Failed to announce to node5000: 403
INFO:Blockchain:Sync loop iteration completed
INFO:Blockchain:Sync loop iteration starting
INFO:Blockchain:Sync loop iteration completed
INFO:Blockchain:Sync loop iteration starting
INFO:Blockchain:Sync loop iteration completed
INFO:Blockchain:Sync loop iteration starting
INFO:Blockchain:Sync loop iteration starting
INFO:aiohttp.access:127.0.0.1 [10/Mar/2025:19:35:22 -0800] "GET /get_chain HTTP/1.1" 200 7915 "-" "Python/3.13 aiohttp/3.11.13"
INFO:aiohttp.access:127.0.0.1 [10/Mar/2025:19:35:22 -0800] "GET /get_chain HTTP/1.1" 200 7915 "-" "Python/3.13 aiohttp/3.11.13"
WARNING:Blockchain:Peer node12649 failed authentication
INFO:aiohttp.access:127.0.0.1 [10/Mar/2025:19:35:22 -0800] "POST /announce_peer HTTP/1.1" 403 119 "-" "Python/3.13 aiohttp/3.11.13"
WARNING:Blockchain:Failed to announce to node5000: 403
WARNING:Blockchain:Peer node12649 failed authentication
INFO:Blockchain:Sync loop iteration completed
INFO:aiohttp.access:127.0.0.1 [10/Mar/2025:19:35:22 -0800] "POST /announce_peer HTTP/1.1" 403 119 "-" "Python/3.13 aiohttp/3.11.13"
WARNING:Blockchain:Failed to announce to node5000: 403
INFO:Blockchain:Sync loop iteration completed
INFO:Blockchain:Sync loop iteration starting
INFO:Blockchain:Sync loop iteration completed
INFO:Blockchain:Sync loop iteration starting
INFO:Blockchain:Sync loop iteration completed
INFO:Blockchain:Sync loop iteration starting
INFO:Blockchain:Sync loop iteration starting
INFO:aiohttp.access:127.0.0.1 [10/Mar/2025:19:35:32 -0800] "GET /get_chain HTTP/1.1" 200 7915 "-" "Python/3.13 aiohttp/3.11.13"
INFO:aiohttp.access:127.0.0.1 [10/Mar/2025:19:35:32 -0800] "GET /get_chain HTTP/1.1" 200 7915 "-" "Python/3.13 aiohttp/3.11.13"
WARNING:Blockchain:Peer node12649 failed authentication
INFO:aiohttp.access:127.0.0.1 [10/Mar/2025:19:35:32 -0800] "POST /announce_peer HTTP/1.1" 403 119 "-" "Python/3.13 aiohttp/3.11.13"
WARNING:Blockchain:Failed to announce to node5000: 403
INFO:Blockchain:Sync loop iteration completed
WARNING:Blockchain:Peer node12649 failed authentication
INFO:aiohttp.access:127.0.0.1 [10/Mar/2025:19:35:32 -0800] "POST /announce_peer HTTP/1.1" 403 119 "-" "Python/3.13 aiohttp/3.11.13"
WARNING:Blockchain:Failed to announce to node5000: 403
INFO:Blockchain:Sync loop iteration completed
INFO:Blockchain:Sync loop iteration starting
INFO:Blockchain:Sync loop iteration completed
INFO:Blockchain:Sync loop iteration starting
INFO:Blockchain:Sync loop iteration completed
INFO:Blockchain:Sync loop iteration starting
INFO:Blockchain:Sync loop iteration starting
INFO:aiohttp.access:127.0.0.1 [10/Mar/2025:19:35:42 -0800] "GET /get_chain HTTP/1.1" 200 7915 "-" "Python/3.13 aiohttp/3.11.13"
INFO:aiohttp.access:127.0.0.1 [10/Mar/2025:19:35:42 -0800] "GET /get_chain HTTP/1.1" 200 7915 "-" "Python/3.13 aiohttp/3.11.13"
WARNING:Blockchain:Peer node12649 failed authentication
INFO:aiohttp.access:127.0.0.1 [10/Mar/2025:19:35:42 -0800] "POST /announce_peer HTTP/1.1" 403 119 "-" "Python/3.13 aiohttp/3.11.13"
WARNING:Blockchain:Peer node12649 failed authentication
WARNING:Blockchain:Failed to announce to node5000: 403
INFO:aiohttp.access:127.0.0.1 [10/Mar/2025:19:35:42 -0800] "POST /announce_peer HTTP/1.1" 403 119 "-" "Python/3.13 aiohttp/3.11.13"
INFO:Blockchain:Sync loop iteration completed
WARNING:Blockchain:Failed to announce to node5000: 403
INFO:Blockchain:Sync loop iteration completed
INFO:aiohttp.access:127.0.0.1 [10/Mar/2025:19:35:52 -0800] "GET /get_chain HTTP/1.1" 200 7915 "-" "Python/3.13 aiohttp/3.11.13"
INFO:Blockchain:Sync loop iteration starting
INFO:Blockchain:Sync loop iteration completed
INFO:Blockchain:Sync loop iteration starting
INFO:Blockchain:Sync loop iteration completed
INFO:aiohttp.access:127.0.0.1 [10/Mar/2025:19:35:52 -0800] "GET /get_chain HTTP/1.1" 200 7915 "-" "Python/3.13 aiohttp/3.11.13"
INFO:aiohttp.access:127.0.0.1 [10/Mar/2025:19:35:52 -0800] "GET /get_peers HTTP/1.1" 200 161 "-" "Python/3.13 aiohttp/3.11.13"
INFO:Blockchain:Initial peer discovery completed
INFO:aiohttp.access:127.0.0.1 [10/Mar/2025:19:35:52 -0800] "GET /get_peers HTTP/1.1" 200 161 "-" "Python/3.13 aiohttp/3.11.13"
INFO:Blockchain:Initial peer discovery completed
INFO:Blockchain:Sync loop iteration starting
INFO:Blockchain:Sync loop iteration starting
INFO:aiohttp.access:127.0.0.1 [10/Mar/2025:19:35:52 -0800] "GET /get_chain HTTP/1.1" 200 7915 "-" "Python/3.13 aiohttp/3.11.13"
INFO:aiohttp.access:127.0.0.1 [10/Mar/2025:19:35:52 -0800] "GET /get_chain HTTP/1.1" 200 7915 "-" "Python/3.13 aiohttp/3.11.13"
WARNING:Blockchain:Peer node12649 failed authentication
INFO:aiohttp.access:127.0.0.1 [10/Mar/2025:19:35:52 -0800] "POST /announce_peer HTTP/1.1" 403 119 "-" "Python/3.13 aiohttp/3.11.13"
WARNING:Blockchain:Failed to announce to node5000: 403
WARNING:Blockchain:Peer node12649 failed authentication
INFO:Blockchain:Sync loop iteration completed
INFO:aiohttp.access:127.0.0.1 [10/Mar/2025:19:35:52 -0800] "POST /announce_peer HTTP/1.1" 403 119 "-" "Python/3.13 aiohttp/3.11.13"
WARNING:Blockchain:Failed to announce to node5000: 403
INFO:Blockchain:Sync loop iteration completed
INFO:Blockchain:Sync loop iteration starting
INFO:Blockchain:Sync loop iteration completed
INFO:Blockchain:Sync loop iteration starting
INFO:Blockchain:Sync loop iteration completed
INFO:Blockchain:Sync loop iteration starting
INFO:Blockchain:Sync loop iteration starting
INFO:aiohttp.access:127.0.0.1 [10/Mar/2025:19:36:02 -0800] "GET /get_chain HTTP/1.1" 200 7915 "-" "Python/3.13 aiohttp/3.11.13"
INFO:aiohttp.access:127.0.0.1 [10/Mar/2025:19:36:02 -0800] "GET /get_chain HTTP/1.1" 200 7915 "-" "Python/3.13 aiohttp/3.11.13"
WARNING:Blockchain:Peer node12649 failed authentication
INFO:aiohttp.access:127.0.0.1 [10/Mar/2025:19:36:02 -0800] "POST /announce_peer HTTP/1.1" 403 119 "-" "Python/3.13 aiohttp/3.11.13"
WARNING:Blockchain:Failed to announce to node5000: 403
WARNING:Blockchain:Peer node12649 failed authentication
INFO:Blockchain:Sync loop iteration completed
INFO:aiohttp.access:127.0.0.1 [10/Mar/2025:19:36:02 -0800] "POST /announce_peer HTTP/1.1" 403 119 "-" "Python/3.13 aiohttp/3.11.13"
WARNING:Blockchain:Failed to announce to node5000: 403
INFO:Blockchain:Sync loop iteration completed
INFO:Blockchain:Mining task started in separate thread
INFO:Blockchain:Starting to mine block 11 with difficulty 1
INFO:Blockchain:Block 11 mined with hash 0e18492a58da125e6d8970302b8b813d64a97954300e808f8e3f5e0bbfe38596
INFO:Blockchain:Transaction c30538ad is coinbase, auto-validated
INFO:Blockchain:Block 0e18492a validated successfully
INFO:Blockchain:Added block 11 to chain: 0e18492a
ERROR:aiohttp.server:Error handling request from 127.0.0.1
Traceback (most recent call last):
  File "C:\Users\jdman\AppData\Local\Packages\PythonSoftwareFoundation.Python.3.13_qbz5n2kfra8p0\LocalCache\local-packages\Python313\site-packages\aiohttp\web_protocol.py", line 480, in _handle_request
    resp = await request_handler(request)
           ^^^^^^^^^^^^^^^^^^^^^^^^^^^^^^
  File "C:\Users\jdman\AppData\Local\Packages\PythonSoftwareFoundation.Python.3.13_qbz5n2kfra8p0\LocalCache\local-packages\Python313\site-packages\aiohttp\web_app.py", line 569, in _handle
    return await handler(request)
           ^^^^^^^^^^^^^^^^^^^^^^
  File "C:\Users\jdman\AppData\Local\Packages\PythonSoftwareFoundation.Python.3.13_qbz5n2kfra8p0\LocalCache\local-packages\Python313\site-packages\aiohttp\web_middlewares.py", line 117, in impl
    return await handler(request)
           ^^^^^^^^^^^^^^^^^^^^^^
  File "C:\Users\jdman\new_coin\network.py", line 28, in middleware
    return await handler(request)
           ^^^^^^^^^^^^^^^^^^^^^^
  File "C:\Users\jdman\new_coin\network.py", line 115, in receive_block
    block = Block.from_dict(data)
  File "C:\Users\jdman\new_coin\blockchain.py", line 158, in from_dict
    transactions = [Transaction.from_dict(t) for t in data["transactions"]]
                                                      ~~~~^^^^^^^^^^^^^^^^
KeyError: 'transactions'
INFO:aiohttp.access:127.0.0.1 [10/Mar/2025:19:36:07 -0800] "POST /receive_block HTTP/1.1" 500 247 "-" "Python/3.13 aiohttp/3.11.13"
WARNING:Blockchain:Failed to send block 11 to node5000
INFO:Blockchain:Successfully mined block 11
ERROR:aiohttp.server:Error handling request from 127.0.0.1
Traceback (most recent call last):
  File "C:\Users\jdman\AppData\Local\Packages\PythonSoftwareFoundation.Python.3.13_qbz5n2kfra8p0\LocalCache\local-packages\Python313\site-packages\aiohttp\web_protocol.py", line 480, in _handle_request
    resp = await request_handler(request)
           ^^^^^^^^^^^^^^^^^^^^^^^^^^^^^^
  File "C:\Users\jdman\AppData\Local\Packages\PythonSoftwareFoundation.Python.3.13_qbz5n2kfra8p0\LocalCache\local-packages\Python313\site-packages\aiohttp\web_app.py", line 569, in _handle
    return await handler(request)
           ^^^^^^^^^^^^^^^^^^^^^^
  File "C:\Users\jdman\AppData\Local\Packages\PythonSoftwareFoundation.Python.3.13_qbz5n2kfra8p0\LocalCache\local-packages\Python313\site-packages\aiohttp\web_middlewares.py", line 117, in impl
    return await handler(request)
           ^^^^^^^^^^^^^^^^^^^^^^
  File "C:\Users\jdman\new_coin\network.py", line 28, in middleware
    return await handler(request)
           ^^^^^^^^^^^^^^^^^^^^^^
  File "C:\Users\jdman\new_coin\network.py", line 115, in receive_block
    block = Block.from_dict(data)
  File "C:\Users\jdman\new_coin\blockchain.py", line 158, in from_dict
    transactions = [Transaction.from_dict(t) for t in data["transactions"]]
                                                      ~~~~^^^^^^^^^^^^^^^^
KeyError: 'transactions'
INFO:aiohttp.access:127.0.0.1 [10/Mar/2025:19:36:07 -0800] "POST /receive_block HTTP/1.1" 500 247 "-" "Python/3.13 aiohttp/3.11.13"
WARNING:Blockchain:Failed to send block 11 to node5000
INFO:Blockchain:Starting to mine block 12 with difficulty 1
INFO:Blockchain:Block 12 mined with hash 0cb171681bf5b8b18e9f12589caa712dc95bb71c5547a2eee8cbbb7c15199842
INFO:Blockchain:Transaction e62f8382 is coinbase, auto-validated
INFO:Blockchain:Block 0cb17168 validated successfully
INFO:Blockchain:Added block 12 to chain: 0cb17168
ERROR:aiohttp.server:Error handling request from 127.0.0.1
Traceback (most recent call last):
  File "C:\Users\jdman\AppData\Local\Packages\PythonSoftwareFoundation.Python.3.13_qbz5n2kfra8p0\LocalCache\local-packages\Python313\site-packages\aiohttp\web_protocol.py", line 480, in _handle_request
    resp = await request_handler(request)
           ^^^^^^^^^^^^^^^^^^^^^^^^^^^^^^
  File "C:\Users\jdman\AppData\Local\Packages\PythonSoftwareFoundation.Python.3.13_qbz5n2kfra8p0\LocalCache\local-packages\Python313\site-packages\aiohttp\web_app.py", line 569, in _handle
    return await handler(request)
           ^^^^^^^^^^^^^^^^^^^^^^
  File "C:\Users\jdman\AppData\Local\Packages\PythonSoftwareFoundation.Python.3.13_qbz5n2kfra8p0\LocalCache\local-packages\Python313\site-packages\aiohttp\web_middlewares.py", line 117, in impl
    return await handler(request)
           ^^^^^^^^^^^^^^^^^^^^^^
  File "C:\Users\jdman\new_coin\network.py", line 28, in middleware
    return await handler(request)
           ^^^^^^^^^^^^^^^^^^^^^^
  File "C:\Users\jdman\new_coin\network.py", line 115, in receive_block
    block = Block.from_dict(data)
  File "C:\Users\jdman\new_coin\blockchain.py", line 158, in from_dict
    transactions = [Transaction.from_dict(t) for t in data["transactions"]]
                                                      ~~~~^^^^^^^^^^^^^^^^
KeyError: 'transactions'
INFO:aiohttp.access:127.0.0.1 [10/Mar/2025:19:36:07 -0800] "POST /receive_block HTTP/1.1" 500 247 "-" "Python/3.13 aiohttp/3.11.13"
WARNING:Blockchain:Failed to send block 12 to node5000
INFO:Blockchain:Successfully mined block 12
ERROR:aiohttp.server:Error handling request from 127.0.0.1
Traceback (most recent call last):
  File "C:\Users\jdman\AppData\Local\Packages\PythonSoftwareFoundation.Python.3.13_qbz5n2kfra8p0\LocalCache\local-packages\Python313\site-packages\aiohttp\web_protocol.py", line 480, in _handle_request
    resp = await request_handler(request)
           ^^^^^^^^^^^^^^^^^^^^^^^^^^^^^^
  File "C:\Users\jdman\AppData\Local\Packages\PythonSoftwareFoundation.Python.3.13_qbz5n2kfra8p0\LocalCache\local-packages\Python313\site-packages\aiohttp\web_app.py", line 569, in _handle
    return await handler(request)
           ^^^^^^^^^^^^^^^^^^^^^^
  File "C:\Users\jdman\AppData\Local\Packages\PythonSoftwareFoundation.Python.3.13_qbz5n2kfra8p0\LocalCache\local-packages\Python313\site-packages\aiohttp\web_middlewares.py", line 117, in impl
    return await handler(request)
           ^^^^^^^^^^^^^^^^^^^^^^
  File "C:\Users\jdman\new_coin\network.py", line 28, in middleware
    return await handler(request)
           ^^^^^^^^^^^^^^^^^^^^^^
  File "C:\Users\jdman\new_coin\network.py", line 115, in receive_block
    block = Block.from_dict(data)
  File "C:\Users\jdman\new_coin\blockchain.py", line 158, in from_dict
    transactions = [Transaction.from_dict(t) for t in data["transactions"]]
                                                      ~~~~^^^^^^^^^^^^^^^^
KeyError: 'transactions'
INFO:aiohttp.access:127.0.0.1 [10/Mar/2025:19:36:07 -0800] "POST /receive_block HTTP/1.1" 500 247 "-" "Python/3.13 aiohttp/3.11.13"
WARNING:Blockchain:Failed to send block 12 to node5000
INFO:Blockchain:Starting to mine block 13 with difficulty 1
INFO:Blockchain:Block 13 mined with hash 09b924255637173b64717830f82ab4cdc30ccf67b9de31c1ed204a525de1505a
INFO:Blockchain:Transaction a61c26fc is coinbase, auto-validated
INFO:Blockchain:Block 09b92425 validated successfully
INFO:Blockchain:Added block 13 to chain: 09b92425
ERROR:aiohttp.server:Error handling request from 127.0.0.1
Traceback (most recent call last):
  File "C:\Users\jdman\AppData\Local\Packages\PythonSoftwareFoundation.Python.3.13_qbz5n2kfra8p0\LocalCache\local-packages\Python313\site-packages\aiohttp\web_protocol.py", line 480, in _handle_request
    resp = await request_handler(request)
           ^^^^^^^^^^^^^^^^^^^^^^^^^^^^^^
  File "C:\Users\jdman\AppData\Local\Packages\PythonSoftwareFoundation.Python.3.13_qbz5n2kfra8p0\LocalCache\local-packages\Python313\site-packages\aiohttp\web_app.py", line 569, in _handle
    return await handler(request)
           ^^^^^^^^^^^^^^^^^^^^^^
  File "C:\Users\jdman\AppData\Local\Packages\PythonSoftwareFoundation.Python.3.13_qbz5n2kfra8p0\LocalCache\local-packages\Python313\site-packages\aiohttp\web_middlewares.py", line 117, in impl
    return await handler(request)
           ^^^^^^^^^^^^^^^^^^^^^^
  File "C:\Users\jdman\new_coin\network.py", line 28, in middleware
    return await handler(request)
           ^^^^^^^^^^^^^^^^^^^^^^
  File "C:\Users\jdman\new_coin\network.py", line 115, in receive_block
    block = Block.from_dict(data)
  File "C:\Users\jdman\new_coin\blockchain.py", line 158, in from_dict
    transactions = [Transaction.from_dict(t) for t in data["transactions"]]
                                                      ~~~~^^^^^^^^^^^^^^^^
KeyError: 'transactions'
INFO:aiohttp.access:127.0.0.1 [10/Mar/2025:19:36:07 -0800] "POST /receive_block HTTP/1.1" 500 247 "-" "Python/3.13 aiohttp/3.11.13"
WARNING:Blockchain:Failed to send block 13 to node5000
INFO:Blockchain:Successfully mined block 13
ERROR:aiohttp.server:Error handling request from 127.0.0.1
Traceback (most recent call last):
  File "C:\Users\jdman\AppData\Local\Packages\PythonSoftwareFoundation.Python.3.13_qbz5n2kfra8p0\LocalCache\local-packages\Python313\site-packages\aiohttp\web_protocol.py", line 480, in _handle_request
    resp = await request_handler(request)
           ^^^^^^^^^^^^^^^^^^^^^^^^^^^^^^
  File "C:\Users\jdman\AppData\Local\Packages\PythonSoftwareFoundation.Python.3.13_qbz5n2kfra8p0\LocalCache\local-packages\Python313\site-packages\aiohttp\web_app.py", line 569, in _handle
    return await handler(request)
           ^^^^^^^^^^^^^^^^^^^^^^
  File "C:\Users\jdman\AppData\Local\Packages\PythonSoftwareFoundation.Python.3.13_qbz5n2kfra8p0\LocalCache\local-packages\Python313\site-packages\aiohttp\web_middlewares.py", line 117, in impl
    return await handler(request)
           ^^^^^^^^^^^^^^^^^^^^^^
  File "C:\Users\jdman\new_coin\network.py", line 28, in middleware
    return await handler(request)
           ^^^^^^^^^^^^^^^^^^^^^^
  File "C:\Users\jdman\new_coin\network.py", line 115, in receive_block
    block = Block.from_dict(data)
  File "C:\Users\jdman\new_coin\blockchain.py", line 158, in from_dict
    transactions = [Transaction.from_dict(t) for t in data["transactions"]]
                                                      ~~~~^^^^^^^^^^^^^^^^
KeyError: 'transactions'
INFO:aiohttp.access:127.0.0.1 [10/Mar/2025:19:36:07 -0800] "POST /receive_block HTTP/1.1" 500 247 "-" "Python/3.13 aiohttp/3.11.13"
WARNING:Blockchain:Failed to send block 13 to node5000
INFO:Blockchain:Starting to mine block 14 with difficulty 1
INFO:Blockchain:Block 14 mined with hash 0556d8935dd7ee3191ec7410f4dd30eaa3faee5df205e5777a5264f84590b7de
INFO:Blockchain:Transaction 4c243494 is coinbase, auto-validated
INFO:Blockchain:Block 0556d893 validated successfully
INFO:Blockchain:Added block 14 to chain: 0556d893
ERROR:aiohttp.server:Error handling request from 127.0.0.1
Traceback (most recent call last):
  File "C:\Users\jdman\AppData\Local\Packages\PythonSoftwareFoundation.Python.3.13_qbz5n2kfra8p0\LocalCache\local-packages\Python313\site-packages\aiohttp\web_protocol.py", line 480, in _handle_request
    resp = await request_handler(request)
           ^^^^^^^^^^^^^^^^^^^^^^^^^^^^^^
  File "C:\Users\jdman\AppData\Local\Packages\PythonSoftwareFoundation.Python.3.13_qbz5n2kfra8p0\LocalCache\local-packages\Python313\site-packages\aiohttp\web_app.py", line 569, in _handle
    return await handler(request)
           ^^^^^^^^^^^^^^^^^^^^^^
  File "C:\Users\jdman\AppData\Local\Packages\PythonSoftwareFoundation.Python.3.13_qbz5n2kfra8p0\LocalCache\local-packages\Python313\site-packages\aiohttp\web_middlewares.py", line 117, in impl
    return await handler(request)
           ^^^^^^^^^^^^^^^^^^^^^^
  File "C:\Users\jdman\new_coin\network.py", line 28, in middleware
    return await handler(request)
           ^^^^^^^^^^^^^^^^^^^^^^
  File "C:\Users\jdman\new_coin\network.py", line 115, in receive_block
    block = Block.from_dict(data)
  File "C:\Users\jdman\new_coin\blockchain.py", line 158, in from_dict
    transactions = [Transaction.from_dict(t) for t in data["transactions"]]
                                                      ~~~~^^^^^^^^^^^^^^^^
KeyError: 'transactions'
INFO:aiohttp.access:127.0.0.1 [10/Mar/2025:19:36:07 -0800] "POST /receive_block HTTP/1.1" 500 247 "-" "Python/3.13 aiohttp/3.11.13"
WARNING:Blockchain:Failed to send block 14 to node5000
INFO:Blockchain:Successfully mined block 14
ERROR:aiohttp.server:Error handling request from 127.0.0.1
Traceback (most recent call last):
  File "C:\Users\jdman\AppData\Local\Packages\PythonSoftwareFoundation.Python.3.13_qbz5n2kfra8p0\LocalCache\local-packages\Python313\site-packages\aiohttp\web_protocol.py", line 480, in _handle_request
    resp = await request_handler(request)
           ^^^^^^^^^^^^^^^^^^^^^^^^^^^^^^
  File "C:\Users\jdman\AppData\Local\Packages\PythonSoftwareFoundation.Python.3.13_qbz5n2kfra8p0\LocalCache\local-packages\Python313\site-packages\aiohttp\web_app.py", line 569, in _handle
    return await handler(request)
           ^^^^^^^^^^^^^^^^^^^^^^
  File "C:\Users\jdman\AppData\Local\Packages\PythonSoftwareFoundation.Python.3.13_qbz5n2kfra8p0\LocalCache\local-packages\Python313\site-packages\aiohttp\web_middlewares.py", line 117, in impl
    return await handler(request)
           ^^^^^^^^^^^^^^^^^^^^^^
  File "C:\Users\jdman\new_coin\network.py", line 28, in middleware
    return await handler(request)
           ^^^^^^^^^^^^^^^^^^^^^^
  File "C:\Users\jdman\new_coin\network.py", line 115, in receive_block
    block = Block.from_dict(data)
  File "C:\Users\jdman\new_coin\blockchain.py", line 158, in from_dict
    transactions = [Transaction.from_dict(t) for t in data["transactions"]]
                                                      ~~~~^^^^^^^^^^^^^^^^
KeyError: 'transactions'
INFO:aiohttp.access:127.0.0.1 [10/Mar/2025:19:36:07 -0800] "POST /receive_block HTTP/1.1" 500 247 "-" "Python/3.13 aiohttp/3.11.13"
WARNING:Blockchain:Failed to send block 14 to node5000
INFO:Blockchain:Starting to mine block 15 with difficulty 1
INFO:Blockchain:Block 15 mined with hash 0c16dd56e435aa946c8ef92fa6e951e48da904b00c3c04a7afcf63a50062cc69
INFO:Blockchain:Transaction c261a769 is coinbase, auto-validated
INFO:Blockchain:Block 0c16dd56 validated successfully
INFO:Blockchain:Added block 15 to chain: 0c16dd56
ERROR:aiohttp.server:Error handling request from 127.0.0.1
Traceback (most recent call last):
  File "C:\Users\jdman\AppData\Local\Packages\PythonSoftwareFoundation.Python.3.13_qbz5n2kfra8p0\LocalCache\local-packages\Python313\site-packages\aiohttp\web_protocol.py", line 480, in _handle_request
    resp = await request_handler(request)
           ^^^^^^^^^^^^^^^^^^^^^^^^^^^^^^
  File "C:\Users\jdman\AppData\Local\Packages\PythonSoftwareFoundation.Python.3.13_qbz5n2kfra8p0\LocalCache\local-packages\Python313\site-packages\aiohttp\web_app.py", line 569, in _handle
    return await handler(request)
           ^^^^^^^^^^^^^^^^^^^^^^
  File "C:\Users\jdman\AppData\Local\Packages\PythonSoftwareFoundation.Python.3.13_qbz5n2kfra8p0\LocalCache\local-packages\Python313\site-packages\aiohttp\web_middlewares.py", line 117, in impl
    return await handler(request)
           ^^^^^^^^^^^^^^^^^^^^^^
  File "C:\Users\jdman\new_coin\network.py", line 28, in middleware
    return await handler(request)
           ^^^^^^^^^^^^^^^^^^^^^^
  File "C:\Users\jdman\new_coin\network.py", line 115, in receive_block
    block = Block.from_dict(data)
  File "C:\Users\jdman\new_coin\blockchain.py", line 158, in from_dict
    transactions = [Transaction.from_dict(t) for t in data["transactions"]]
                                                      ~~~~^^^^^^^^^^^^^^^^
KeyError: 'transactions'
INFO:aiohttp.access:127.0.0.1 [10/Mar/2025:19:36:08 -0800] "POST /receive_block HTTP/1.1" 500 247 "-" "Python/3.13 aiohttp/3.11.13"
WARNING:Blockchain:Failed to send block 15 to node5000
INFO:Blockchain:Successfully mined block 15
ERROR:aiohttp.server:Error handling request from 127.0.0.1
Traceback (most recent call last):
  File "C:\Users\jdman\AppData\Local\Packages\PythonSoftwareFoundation.Python.3.13_qbz5n2kfra8p0\LocalCache\local-packages\Python313\site-packages\aiohttp\web_protocol.py", line 480, in _handle_request
    resp = await request_handler(request)
           ^^^^^^^^^^^^^^^^^^^^^^^^^^^^^^
  File "C:\Users\jdman\AppData\Local\Packages\PythonSoftwareFoundation.Python.3.13_qbz5n2kfra8p0\LocalCache\local-packages\Python313\site-packages\aiohttp\web_app.py", line 569, in _handle
    return await handler(request)
           ^^^^^^^^^^^^^^^^^^^^^^
  File "C:\Users\jdman\AppData\Local\Packages\PythonSoftwareFoundation.Python.3.13_qbz5n2kfra8p0\LocalCache\local-packages\Python313\site-packages\aiohttp\web_middlewares.py", line 117, in impl
    return await handler(request)
           ^^^^^^^^^^^^^^^^^^^^^^
  File "C:\Users\jdman\new_coin\network.py", line 28, in middleware
    return await handler(request)
           ^^^^^^^^^^^^^^^^^^^^^^
  File "C:\Users\jdman\new_coin\network.py", line 115, in receive_block
    block = Block.from_dict(data)
  File "C:\Users\jdman\new_coin\blockchain.py", line 158, in from_dict
    transactions = [Transaction.from_dict(t) for t in data["transactions"]]
                                                      ~~~~^^^^^^^^^^^^^^^^
KeyError: 'transactions'
INFO:aiohttp.access:127.0.0.1 [10/Mar/2025:19:36:08 -0800] "POST /receive_block HTTP/1.1" 500 247 "-" "Python/3.13 aiohttp/3.11.13"
WARNING:Blockchain:Failed to send block 15 to node5000
INFO:Blockchain:Starting to mine block 16 with difficulty 1
INFO:Blockchain:Block 16 mined with hash 091e7d60728bc4e2cd4d9865936f1f18eec3ff9f6b58b02332a96dff8a3ba8e6
INFO:Blockchain:Transaction c15482f2 is coinbase, auto-validated
INFO:Blockchain:Block 091e7d60 validated successfully
INFO:Blockchain:Added block 16 to chain: 091e7d60
ERROR:aiohttp.server:Error handling request from 127.0.0.1
Traceback (most recent call last):
  File "C:\Users\jdman\AppData\Local\Packages\PythonSoftwareFoundation.Python.3.13_qbz5n2kfra8p0\LocalCache\local-packages\Python313\site-packages\aiohttp\web_protocol.py", line 480, in _handle_request
    resp = await request_handler(request)
           ^^^^^^^^^^^^^^^^^^^^^^^^^^^^^^
  File "C:\Users\jdman\AppData\Local\Packages\PythonSoftwareFoundation.Python.3.13_qbz5n2kfra8p0\LocalCache\local-packages\Python313\site-packages\aiohttp\web_app.py", line 569, in _handle
    return await handler(request)
           ^^^^^^^^^^^^^^^^^^^^^^
  File "C:\Users\jdman\AppData\Local\Packages\PythonSoftwareFoundation.Python.3.13_qbz5n2kfra8p0\LocalCache\local-packages\Python313\site-packages\aiohttp\web_middlewares.py", line 117, in impl
    return await handler(request)
           ^^^^^^^^^^^^^^^^^^^^^^
  File "C:\Users\jdman\new_coin\network.py", line 28, in middleware
    return await handler(request)
           ^^^^^^^^^^^^^^^^^^^^^^
  File "C:\Users\jdman\new_coin\network.py", line 115, in receive_block
    block = Block.from_dict(data)
  File "C:\Users\jdman\new_coin\blockchain.py", line 158, in from_dict
    transactions = [Transaction.from_dict(t) for t in data["transactions"]]
                                                      ~~~~^^^^^^^^^^^^^^^^
KeyError: 'transactions'
INFO:aiohttp.access:127.0.0.1 [10/Mar/2025:19:36:08 -0800] "POST /receive_block HTTP/1.1" 500 247 "-" "Python/3.13 aiohttp/3.11.13"
WARNING:Blockchain:Failed to send block 16 to node5000
INFO:Blockchain:Successfully mined block 16
ERROR:aiohttp.server:Error handling request from 127.0.0.1
Traceback (most recent call last):
  File "C:\Users\jdman\AppData\Local\Packages\PythonSoftwareFoundation.Python.3.13_qbz5n2kfra8p0\LocalCache\local-packages\Python313\site-packages\aiohttp\web_protocol.py", line 480, in _handle_request
    resp = await request_handler(request)
           ^^^^^^^^^^^^^^^^^^^^^^^^^^^^^^
  File "C:\Users\jdman\AppData\Local\Packages\PythonSoftwareFoundation.Python.3.13_qbz5n2kfra8p0\LocalCache\local-packages\Python313\site-packages\aiohttp\web_app.py", line 569, in _handle
    return await handler(request)
           ^^^^^^^^^^^^^^^^^^^^^^
  File "C:\Users\jdman\AppData\Local\Packages\PythonSoftwareFoundation.Python.3.13_qbz5n2kfra8p0\LocalCache\local-packages\Python313\site-packages\aiohttp\web_middlewares.py", line 117, in impl
    return await handler(request)
           ^^^^^^^^^^^^^^^^^^^^^^
  File "C:\Users\jdman\new_coin\network.py", line 28, in middleware
    return await handler(request)
           ^^^^^^^^^^^^^^^^^^^^^^
  File "C:\Users\jdman\new_coin\network.py", line 115, in receive_block
    block = Block.from_dict(data)
  File "C:\Users\jdman\new_coin\blockchain.py", line 158, in from_dict
    transactions = [Transaction.from_dict(t) for t in data["transactions"]]
                                                      ~~~~^^^^^^^^^^^^^^^^
KeyError: 'transactions'
INFO:aiohttp.access:127.0.0.1 [10/Mar/2025:19:36:08 -0800] "POST /receive_block HTTP/1.1" 500 247 "-" "Python/3.13 aiohttp/3.11.13"
WARNING:Blockchain:Failed to send block 16 to node5000
INFO:Blockchain:Starting to mine block 17 with difficulty 1
INFO:Blockchain:Block 17 mined with hash 005f50bbf5634f4a222039c1a2adb117394bb14b48fc6be54e9e94a746526b0a
INFO:Blockchain:Transaction 0988f5d3 is coinbase, auto-validated
INFO:Blockchain:Block 005f50bb validated successfully
INFO:Blockchain:Added block 17 to chain: 005f50bb
ERROR:aiohttp.server:Error handling request from 127.0.0.1
Traceback (most recent call last):
  File "C:\Users\jdman\AppData\Local\Packages\PythonSoftwareFoundation.Python.3.13_qbz5n2kfra8p0\LocalCache\local-packages\Python313\site-packages\aiohttp\web_protocol.py", line 480, in _handle_request
    resp = await request_handler(request)
           ^^^^^^^^^^^^^^^^^^^^^^^^^^^^^^
  File "C:\Users\jdman\AppData\Local\Packages\PythonSoftwareFoundation.Python.3.13_qbz5n2kfra8p0\LocalCache\local-packages\Python313\site-packages\aiohttp\web_app.py", line 569, in _handle
    return await handler(request)
           ^^^^^^^^^^^^^^^^^^^^^^
  File "C:\Users\jdman\AppData\Local\Packages\PythonSoftwareFoundation.Python.3.13_qbz5n2kfra8p0\LocalCache\local-packages\Python313\site-packages\aiohttp\web_middlewares.py", line 117, in impl
    return await handler(request)
           ^^^^^^^^^^^^^^^^^^^^^^
  File "C:\Users\jdman\new_coin\network.py", line 28, in middleware
    return await handler(request)
           ^^^^^^^^^^^^^^^^^^^^^^
  File "C:\Users\jdman\new_coin\network.py", line 115, in receive_block
    block = Block.from_dict(data)
  File "C:\Users\jdman\new_coin\blockchain.py", line 158, in from_dict
    transactions = [Transaction.from_dict(t) for t in data["transactions"]]
                                                      ~~~~^^^^^^^^^^^^^^^^
KeyError: 'transactions'
INFO:aiohttp.access:127.0.0.1 [10/Mar/2025:19:36:08 -0800] "POST /receive_block HTTP/1.1" 500 247 "-" "Python/3.13 aiohttp/3.11.13"
WARNING:Blockchain:Failed to send block 17 to node5000
INFO:Blockchain:Successfully mined block 17
ERROR:aiohttp.server:Error handling request from 127.0.0.1
Traceback (most recent call last):
  File "C:\Users\jdman\AppData\Local\Packages\PythonSoftwareFoundation.Python.3.13_qbz5n2kfra8p0\LocalCache\local-packages\Python313\site-packages\aiohttp\web_protocol.py", line 480, in _handle_request
    resp = await request_handler(request)
           ^^^^^^^^^^^^^^^^^^^^^^^^^^^^^^
  File "C:\Users\jdman\AppData\Local\Packages\PythonSoftwareFoundation.Python.3.13_qbz5n2kfra8p0\LocalCache\local-packages\Python313\site-packages\aiohttp\web_app.py", line 569, in _handle
    return await handler(request)
           ^^^^^^^^^^^^^^^^^^^^^^
  File "C:\Users\jdman\AppData\Local\Packages\PythonSoftwareFoundation.Python.3.13_qbz5n2kfra8p0\LocalCache\local-packages\Python313\site-packages\aiohttp\web_middlewares.py", line 117, in impl
    return await handler(request)
           ^^^^^^^^^^^^^^^^^^^^^^
  File "C:\Users\jdman\new_coin\network.py", line 28, in middleware
    return await handler(request)
           ^^^^^^^^^^^^^^^^^^^^^^
  File "C:\Users\jdman\new_coin\network.py", line 115, in receive_block
    block = Block.from_dict(data)
  File "C:\Users\jdman\new_coin\blockchain.py", line 158, in from_dict
    transactions = [Transaction.from_dict(t) for t in data["transactions"]]
                                                      ~~~~^^^^^^^^^^^^^^^^
KeyError: 'transactions'
INFO:aiohttp.access:127.0.0.1 [10/Mar/2025:19:36:08 -0800] "POST /receive_block HTTP/1.1" 500 247 "-" "Python/3.13 aiohttp/3.11.13"
WARNING:Blockchain:Failed to send block 17 to node5000
INFO:Blockchain:Starting to mine block 18 with difficulty 1
INFO:Blockchain:Block 18 mined with hash 0c9ea76a7d1dc1829eba6e828233646f1511b13e2a1b87a7b6a7d4395324b86f
INFO:Blockchain:Transaction 1a24527e is coinbase, auto-validated
INFO:Blockchain:Block 0c9ea76a validated successfully
INFO:Blockchain:Added block 18 to chain: 0c9ea76a
ERROR:aiohttp.server:Error handling request from 127.0.0.1
Traceback (most recent call last):
  File "C:\Users\jdman\AppData\Local\Packages\PythonSoftwareFoundation.Python.3.13_qbz5n2kfra8p0\LocalCache\local-packages\Python313\site-packages\aiohttp\web_protocol.py", line 480, in _handle_request
    resp = await request_handler(request)
           ^^^^^^^^^^^^^^^^^^^^^^^^^^^^^^
  File "C:\Users\jdman\AppData\Local\Packages\PythonSoftwareFoundation.Python.3.13_qbz5n2kfra8p0\LocalCache\local-packages\Python313\site-packages\aiohttp\web_app.py", line 569, in _handle
    return await handler(request)
           ^^^^^^^^^^^^^^^^^^^^^^
  File "C:\Users\jdman\AppData\Local\Packages\PythonSoftwareFoundation.Python.3.13_qbz5n2kfra8p0\LocalCache\local-packages\Python313\site-packages\aiohttp\web_middlewares.py", line 117, in impl
    return await handler(request)
           ^^^^^^^^^^^^^^^^^^^^^^
  File "C:\Users\jdman\new_coin\network.py", line 28, in middleware
    return await handler(request)
           ^^^^^^^^^^^^^^^^^^^^^^
  File "C:\Users\jdman\new_coin\network.py", line 115, in receive_block
    block = Block.from_dict(data)
  File "C:\Users\jdman\new_coin\blockchain.py", line 158, in from_dict
    transactions = [Transaction.from_dict(t) for t in data["transactions"]]
                                                      ~~~~^^^^^^^^^^^^^^^^
KeyError: 'transactions'
INFO:aiohttp.access:127.0.0.1 [10/Mar/2025:19:36:08 -0800] "POST /receive_block HTTP/1.1" 500 247 "-" "Python/3.13 aiohttp/3.11.13"
WARNING:Blockchain:Failed to send block 18 to node5000
INFO:Blockchain:Successfully mined block 18
ERROR:aiohttp.server:Error handling request from 127.0.0.1
Traceback (most recent call last):
  File "C:\Users\jdman\AppData\Local\Packages\PythonSoftwareFoundation.Python.3.13_qbz5n2kfra8p0\LocalCache\local-packages\Python313\site-packages\aiohttp\web_protocol.py", line 480, in _handle_request
    resp = await request_handler(request)
           ^^^^^^^^^^^^^^^^^^^^^^^^^^^^^^
  File "C:\Users\jdman\AppData\Local\Packages\PythonSoftwareFoundation.Python.3.13_qbz5n2kfra8p0\LocalCache\local-packages\Python313\site-packages\aiohttp\web_app.py", line 569, in _handle
    return await handler(request)
           ^^^^^^^^^^^^^^^^^^^^^^
  File "C:\Users\jdman\AppData\Local\Packages\PythonSoftwareFoundation.Python.3.13_qbz5n2kfra8p0\LocalCache\local-packages\Python313\site-packages\aiohttp\web_middlewares.py", line 117, in impl
    return await handler(request)
           ^^^^^^^^^^^^^^^^^^^^^^
  File "C:\Users\jdman\new_coin\network.py", line 28, in middleware
    return await handler(request)
           ^^^^^^^^^^^^^^^^^^^^^^
  File "C:\Users\jdman\new_coin\network.py", line 115, in receive_block
    block = Block.from_dict(data)
  File "C:\Users\jdman\new_coin\blockchain.py", line 158, in from_dict
    transactions = [Transaction.from_dict(t) for t in data["transactions"]]
                                                      ~~~~^^^^^^^^^^^^^^^^
KeyError: 'transactions'
INFO:aiohttp.access:127.0.0.1 [10/Mar/2025:19:36:08 -0800] "POST /receive_block HTTP/1.1" 500 247 "-" "Python/3.13 aiohttp/3.11.13"
WARNING:Blockchain:Failed to send block 18 to node5000
INFO:Blockchain:Starting to mine block 19 with difficulty 1
INFO:Blockchain:Block 19 mined with hash 0ef1aaa0f2a4611534b37b431f2c40cbf0fcb53fb21725b964297486dcb662c3
INFO:Blockchain:Transaction 6d376d68 is coinbase, auto-validated
INFO:Blockchain:Block 0ef1aaa0 validated successfully
INFO:Blockchain:Added block 19 to chain: 0ef1aaa0
ERROR:aiohttp.server:Error handling request from 127.0.0.1
Traceback (most recent call last):
  File "C:\Users\jdman\AppData\Local\Packages\PythonSoftwareFoundation.Python.3.13_qbz5n2kfra8p0\LocalCache\local-packages\Python313\site-packages\aiohttp\web_protocol.py", line 480, in _handle_request
    resp = await request_handler(request)
           ^^^^^^^^^^^^^^^^^^^^^^^^^^^^^^
  File "C:\Users\jdman\AppData\Local\Packages\PythonSoftwareFoundation.Python.3.13_qbz5n2kfra8p0\LocalCache\local-packages\Python313\site-packages\aiohttp\web_app.py", line 569, in _handle
    return await handler(request)
           ^^^^^^^^^^^^^^^^^^^^^^
  File "C:\Users\jdman\AppData\Local\Packages\PythonSoftwareFoundation.Python.3.13_qbz5n2kfra8p0\LocalCache\local-packages\Python313\site-packages\aiohttp\web_middlewares.py", line 117, in impl
    return await handler(request)
           ^^^^^^^^^^^^^^^^^^^^^^
  File "C:\Users\jdman\new_coin\network.py", line 28, in middleware
    return await handler(request)
           ^^^^^^^^^^^^^^^^^^^^^^
  File "C:\Users\jdman\new_coin\network.py", line 115, in receive_block
    block = Block.from_dict(data)
  File "C:\Users\jdman\new_coin\blockchain.py", line 158, in from_dict
    transactions = [Transaction.from_dict(t) for t in data["transactions"]]
                                                      ~~~~^^^^^^^^^^^^^^^^
KeyError: 'transactions'
INFO:aiohttp.access:127.0.0.1 [10/Mar/2025:19:36:09 -0800] "POST /receive_block HTTP/1.1" 500 247 "-" "Python/3.13 aiohttp/3.11.13"
WARNING:Blockchain:Failed to send block 19 to node5000
INFO:Blockchain:Successfully mined block 19
ERROR:aiohttp.server:Error handling request from 127.0.0.1
Traceback (most recent call last):
  File "C:\Users\jdman\AppData\Local\Packages\PythonSoftwareFoundation.Python.3.13_qbz5n2kfra8p0\LocalCache\local-packages\Python313\site-packages\aiohttp\web_protocol.py", line 480, in _handle_request
    resp = await request_handler(request)
           ^^^^^^^^^^^^^^^^^^^^^^^^^^^^^^
  File "C:\Users\jdman\AppData\Local\Packages\PythonSoftwareFoundation.Python.3.13_qbz5n2kfra8p0\LocalCache\local-packages\Python313\site-packages\aiohttp\web_app.py", line 569, in _handle
    return await handler(request)
           ^^^^^^^^^^^^^^^^^^^^^^
  File "C:\Users\jdman\AppData\Local\Packages\PythonSoftwareFoundation.Python.3.13_qbz5n2kfra8p0\LocalCache\local-packages\Python313\site-packages\aiohttp\web_middlewares.py", line 117, in impl
    return await handler(request)
           ^^^^^^^^^^^^^^^^^^^^^^
  File "C:\Users\jdman\new_coin\network.py", line 28, in middleware
    return await handler(request)
           ^^^^^^^^^^^^^^^^^^^^^^
  File "C:\Users\jdman\new_coin\network.py", line 115, in receive_block
    block = Block.from_dict(data)
  File "C:\Users\jdman\new_coin\blockchain.py", line 158, in from_dict
    transactions = [Transaction.from_dict(t) for t in data["transactions"]]
                                                      ~~~~^^^^^^^^^^^^^^^^
KeyError: 'transactions'
INFO:aiohttp.access:127.0.0.1 [10/Mar/2025:19:36:09 -0800] "POST /receive_block HTTP/1.1" 500 247 "-" "Python/3.13 aiohttp/3.11.13"
WARNING:Blockchain:Failed to send block 19 to node5000
INFO:Blockchain:Starting to mine block 20 with difficulty 1
INFO:Blockchain:Block 20 mined with hash 0d181ae21e7f86b297fac74718f515fe196c15db3234e9b50e00f167d32aec07
INFO:Blockchain:Transaction 8f08eb9e is coinbase, auto-validated
INFO:Blockchain:Block 0d181ae2 validated successfully
INFO:Blockchain:Added block 20 to chain: 0d181ae2
ERROR:aiohttp.server:Error handling request from 127.0.0.1
Traceback (most recent call last):
  File "C:\Users\jdman\AppData\Local\Packages\PythonSoftwareFoundation.Python.3.13_qbz5n2kfra8p0\LocalCache\local-packages\Python313\site-packages\aiohttp\web_protocol.py", line 480, in _handle_request
    resp = await request_handler(request)
           ^^^^^^^^^^^^^^^^^^^^^^^^^^^^^^
  File "C:\Users\jdman\AppData\Local\Packages\PythonSoftwareFoundation.Python.3.13_qbz5n2kfra8p0\LocalCache\local-packages\Python313\site-packages\aiohttp\web_app.py", line 569, in _handle
    return await handler(request)
           ^^^^^^^^^^^^^^^^^^^^^^
  File "C:\Users\jdman\AppData\Local\Packages\PythonSoftwareFoundation.Python.3.13_qbz5n2kfra8p0\LocalCache\local-packages\Python313\site-packages\aiohttp\web_middlewares.py", line 117, in impl
    return await handler(request)
           ^^^^^^^^^^^^^^^^^^^^^^
  File "C:\Users\jdman\new_coin\network.py", line 28, in middleware
    return await handler(request)
           ^^^^^^^^^^^^^^^^^^^^^^
  File "C:\Users\jdman\new_coin\network.py", line 115, in receive_block
    block = Block.from_dict(data)
  File "C:\Users\jdman\new_coin\blockchain.py", line 158, in from_dict
    transactions = [Transaction.from_dict(t) for t in data["transactions"]]
                                                      ~~~~^^^^^^^^^^^^^^^^
KeyError: 'transactions'
INFO:aiohttp.access:127.0.0.1 [10/Mar/2025:19:36:09 -0800] "POST /receive_block HTTP/1.1" 500 247 "-" "Python/3.13 aiohttp/3.11.13"
WARNING:Blockchain:Failed to send block 20 to node5000
INFO:Blockchain:Successfully mined block 20
ERROR:aiohttp.server:Error handling request from 127.0.0.1
Traceback (most recent call last):
  File "C:\Users\jdman\AppData\Local\Packages\PythonSoftwareFoundation.Python.3.13_qbz5n2kfra8p0\LocalCache\local-packages\Python313\site-packages\aiohttp\web_protocol.py", line 480, in _handle_request
    resp = await request_handler(request)
           ^^^^^^^^^^^^^^^^^^^^^^^^^^^^^^
  File "C:\Users\jdman\AppData\Local\Packages\PythonSoftwareFoundation.Python.3.13_qbz5n2kfra8p0\LocalCache\local-packages\Python313\site-packages\aiohttp\web_app.py", line 569, in _handle
    return await handler(request)
           ^^^^^^^^^^^^^^^^^^^^^^
  File "C:\Users\jdman\AppData\Local\Packages\PythonSoftwareFoundation.Python.3.13_qbz5n2kfra8p0\LocalCache\local-packages\Python313\site-packages\aiohttp\web_middlewares.py", line 117, in impl
    return await handler(request)
           ^^^^^^^^^^^^^^^^^^^^^^
  File "C:\Users\jdman\new_coin\network.py", line 28, in middleware
    return await handler(request)
           ^^^^^^^^^^^^^^^^^^^^^^
  File "C:\Users\jdman\new_coin\network.py", line 115, in receive_block
    block = Block.from_dict(data)
  File "C:\Users\jdman\new_coin\blockchain.py", line 158, in from_dict
    transactions = [Transaction.from_dict(t) for t in data["transactions"]]
                                                      ~~~~^^^^^^^^^^^^^^^^
KeyError: 'transactions'
INFO:aiohttp.access:127.0.0.1 [10/Mar/2025:19:36:09 -0800] "POST /receive_block HTTP/1.1" 500 247 "-" "Python/3.13 aiohttp/3.11.13"
WARNING:Blockchain:Failed to send block 20 to node5000
INFO:Blockchain:Starting to mine block 21 with difficulty 1
INFO:Blockchain:Block 21 mined with hash 01c3607525cd92e6c91bd5a03666eb2dcfc5a38fa4ddaac717fec1b00afb79dd
INFO:Blockchain:Transaction 36fa5fac is coinbase, auto-validated
INFO:Blockchain:Block 01c36075 validated successfully
INFO:Blockchain:Added block 21 to chain: 01c36075
ERROR:aiohttp.server:Error handling request from 127.0.0.1
Traceback (most recent call last):
  File "C:\Users\jdman\AppData\Local\Packages\PythonSoftwareFoundation.Python.3.13_qbz5n2kfra8p0\LocalCache\local-packages\Python313\site-packages\aiohttp\web_protocol.py", line 480, in _handle_request
    resp = await request_handler(request)
           ^^^^^^^^^^^^^^^^^^^^^^^^^^^^^^
  File "C:\Users\jdman\AppData\Local\Packages\PythonSoftwareFoundation.Python.3.13_qbz5n2kfra8p0\LocalCache\local-packages\Python313\site-packages\aiohttp\web_app.py", line 569, in _handle
    return await handler(request)
           ^^^^^^^^^^^^^^^^^^^^^^
  File "C:\Users\jdman\AppData\Local\Packages\PythonSoftwareFoundation.Python.3.13_qbz5n2kfra8p0\LocalCache\local-packages\Python313\site-packages\aiohttp\web_middlewares.py", line 117, in impl
    return await handler(request)
           ^^^^^^^^^^^^^^^^^^^^^^
  File "C:\Users\jdman\new_coin\network.py", line 28, in middleware
    return await handler(request)
           ^^^^^^^^^^^^^^^^^^^^^^
  File "C:\Users\jdman\new_coin\network.py", line 115, in receive_block
    block = Block.from_dict(data)
  File "C:\Users\jdman\new_coin\blockchain.py", line 158, in from_dict
    transactions = [Transaction.from_dict(t) for t in data["transactions"]]
                                                      ~~~~^^^^^^^^^^^^^^^^
KeyError: 'transactions'
INFO:aiohttp.access:127.0.0.1 [10/Mar/2025:19:36:09 -0800] "POST /receive_block HTTP/1.1" 500 247 "-" "Python/3.13 aiohttp/3.11.13"
WARNING:Blockchain:Failed to send block 21 to node5000
INFO:Blockchain:Successfully mined block 21
ERROR:aiohttp.server:Error handling request from 127.0.0.1
Traceback (most recent call last):
  File "C:\Users\jdman\AppData\Local\Packages\PythonSoftwareFoundation.Python.3.13_qbz5n2kfra8p0\LocalCache\local-packages\Python313\site-packages\aiohttp\web_protocol.py", line 480, in _handle_request
    resp = await request_handler(request)
           ^^^^^^^^^^^^^^^^^^^^^^^^^^^^^^
  File "C:\Users\jdman\AppData\Local\Packages\PythonSoftwareFoundation.Python.3.13_qbz5n2kfra8p0\LocalCache\local-packages\Python313\site-packages\aiohttp\web_app.py", line 569, in _handle
    return await handler(request)
           ^^^^^^^^^^^^^^^^^^^^^^
  File "C:\Users\jdman\AppData\Local\Packages\PythonSoftwareFoundation.Python.3.13_qbz5n2kfra8p0\LocalCache\local-packages\Python313\site-packages\aiohttp\web_middlewares.py", line 117, in impl
    return await handler(request)
           ^^^^^^^^^^^^^^^^^^^^^^
  File "C:\Users\jdman\new_coin\network.py", line 28, in middleware
    return await handler(request)
           ^^^^^^^^^^^^^^^^^^^^^^
  File "C:\Users\jdman\new_coin\network.py", line 115, in receive_block
    block = Block.from_dict(data)
  File "C:\Users\jdman\new_coin\blockchain.py", line 158, in from_dict
    transactions = [Transaction.from_dict(t) for t in data["transactions"]]
                                                      ~~~~^^^^^^^^^^^^^^^^
KeyError: 'transactions'
INFO:aiohttp.access:127.0.0.1 [10/Mar/2025:19:36:09 -0800] "POST /receive_block HTTP/1.1" 500 247 "-" "Python/3.13 aiohttp/3.11.13"
WARNING:Blockchain:Failed to send block 21 to node5000
INFO:Blockchain:Mining thread stopped
INFO:Blockchain:Initial peer discovery completed
INFO:Blockchain:Initial peer discovery completed
INFO:Blockchain:Sync loop iteration starting
INFO:Blockchain:Sync loop iteration completed
INFO:Blockchain:Sync loop iteration starting
INFO:Blockchain:Sync loop iteration completed
INFO:Blockchain:Sync loop iteration starting
INFO:Blockchain:Sync loop iteration starting
INFO:aiohttp.access:127.0.0.1 [10/Mar/2025:19:36:12 -0800] "GET /get_chain HTTP/1.1" 200 7915 "-" "Python/3.13 aiohttp/3.11.13"
INFO:aiohttp.access:127.0.0.1 [10/Mar/2025:19:36:12 -0800] "GET /get_chain HTTP/1.1" 200 7915 "-" "Python/3.13 aiohttp/3.11.13"
WARNING:Blockchain:Peer node12649 failed authentication
INFO:aiohttp.access:127.0.0.1 [10/Mar/2025:19:36:12 -0800] "POST /announce_peer HTTP/1.1" 403 119 "-" "Python/3.13 aiohttp/3.11.13"
WARNING:Blockchain:Failed to announce to node5000: 403
INFO:Blockchain:Sync loop iteration completed
WARNING:Blockchain:Peer node12649 failed authentication
INFO:aiohttp.access:127.0.0.1 [10/Mar/2025:19:36:12 -0800] "POST /announce_peer HTTP/1.1" 403 119 "-" "Python/3.13 aiohttp/3.11.13"
WARNING:Blockchain:Failed to announce to node5000: 403
INFO:Blockchain:Sync loop iteration completed
INFO:Blockchain:Sync loop iteration starting
INFO:Blockchain:Sync loop iteration completed
INFO:Blockchain:Sync loop iteration starting
INFO:Blockchain:Sync loop iteration completed
INFO:Blockchain:Sync loop iteration starting
INFO:Blockchain:Sync loop iteration starting
INFO:aiohttp.access:127.0.0.1 [10/Mar/2025:19:36:22 -0800] "GET /get_chain HTTP/1.1" 200 7915 "-" "Python/3.13 aiohttp/3.11.13"
INFO:aiohttp.access:127.0.0.1 [10/Mar/2025:19:36:22 -0800] "GET /get_chain HTTP/1.1" 200 7915 "-" "Python/3.13 aiohttp/3.11.13"
WARNING:Blockchain:Peer node12649 failed authentication
INFO:aiohttp.access:127.0.0.1 [10/Mar/2025:19:36:22 -0800] "POST /announce_peer HTTP/1.1" 403 119 "-" "Python/3.13 aiohttp/3.11.13"
WARNING:Blockchain:Failed to announce to node5000: 403
INFO:Blockchain:Sync loop iteration completed
WARNING:Blockchain:Peer node12649 failed authentication
INFO:aiohttp.access:127.0.0.1 [10/Mar/2025:19:36:22 -0800] "POST /announce_peer HTTP/1.1" 403 119 "-" "Python/3.13 aiohttp/3.11.13"
WARNING:Blockchain:Failed to announce to node5000: 403
INFO:Blockchain:Sync loop iteration completed
INFO:Blockchain:Sync loop iteration starting
INFO:Blockchain:Sync loop iteration completed
INFO:Blockchain:Sync loop iteration starting
INFO:Blockchain:Sync loop iteration completed
INFO:Blockchain:Sync loop iteration starting
INFO:Blockchain:Sync loop iteration starting
INFO:aiohttp.access:127.0.0.1 [10/Mar/2025:19:36:32 -0800] "GET /get_chain HTTP/1.1" 200 7915 "-" "Python/3.13 aiohttp/3.11.13"
INFO:aiohttp.access:127.0.0.1 [10/Mar/2025:19:36:32 -0800] "GET /get_chain HTTP/1.1" 200 7915 "-" "Python/3.13 aiohttp/3.11.13"
WARNING:Blockchain:Peer node12649 failed authentication
INFO:aiohttp.access:127.0.0.1 [10/Mar/2025:19:36:32 -0800] "POST /announce_peer HTTP/1.1" 403 119 "-" "Python/3.13 aiohttp/3.11.13"
WARNING:Blockchain:Failed to announce to node5000: 403
WARNING:Blockchain:Peer node12649 failed authentication
INFO:aiohttp.access:127.0.0.1 [10/Mar/2025:19:36:32 -0800] "POST /announce_peer HTTP/1.1" 403 119 "-" "Python/3.13 aiohttp/3.11.13"
WARNING:Blockchain:Failed to announce to node5000: 403
INFO:Blockchain:Sync loop iteration completed
WARNING:Blockchain:No active mining thread to stop
INFO:Blockchain:GUI main loop exited
WARNING:Blockchain:No active mining thread to stop
INFO:Blockchain:GUI main loop exited
